<?xml version="1.0"?>
<robot name="myrobot">
    <link name="base">
        <visual>
            <geometry>
                <mesh filename="Base.stl" scale="0.001 0.001 0.001"/>
            </geometry>
            <material name="base_color">
                <color rgba="0 0 1 1"/>
            </material>
        </visual>
        <collision>
            <geometry>
                <mesh filename="Base.stl" scale="0.001 0.001 0.001"/>
            </geometry >
        </collision >
        <inertial>
            <mass value="0.651"/>
            <origin xyz="0.00728 0.00019 0.01758"/>
            <inertia ixx="0.001210405" ixy="-0.000000274" ixz="-0.000295998" iyy="0.001556213" iyz="0.000001807 " izz="0.00116248"/>
        </inertial>
    </link>

    <link name="head">
        <visual>
            <geometry>
                <mesh filename="Head.stl" scale="0.001 0.001 0.001"/>
            </geometry>
            <material name="head_color">
                <color rgba="1 1 1 1"/>
            </material>
        </visual>
        <collision>
            <geometry>
                <mesh filename="Head.stl" scale="0.001 0.001 0.001"/>
            </geometry >
        </collision >
        <inertial>
            <mass value="0.150"/>
            <origin xyz="0.0406	0.00172	0.0008"/>
            <inertia ixx="0.000074914" ixy="0.000001425" ixz="0.000000633" iyy="0.000004174" iyz="-0.000001279" izz="0.000074235"/>
        </inertial>
    </link>
    <joint name="base_TO_head" type="revolute">
        <parent link="base"/>
        <child link="head"/>
        <origin xyz="0.0542 -0.00178 0.0463"/>
        <axis xyz="0 1 0"/>
        <limit lower="-1.57" upper="0" effort="1.667" velocity="5.5"/>
    </joint>

    <link name="left_hip">
        <visual>
            <geometry>
                <mesh filename="Left_Hip.stl" scale="0.001 0.001 0.001"/>
            </geometry>
            <material name="hip_color">
                <color rgba="0 1 1 1"/>
            </material>
        </visual>
        <collision>
            <geometry>
                <mesh filename="Left_Hip.stl" scale="0.001 0.001 0.001"/>
            </geometry >
        </collision >
        <inertial>
            <mass value="0.137"/>
            <origin xyz="-0.03864	0.00843	-0.00007"/>
            <inertia ixx="0.000045031" ixy="0.000002019" ixz="-0.000000001" iyy="0.000030577" iyz="0.000000404" izz="0.000068434"/>
        </inertial>
    </link>
    <joint name="base_TO_left_hip" type="revolute">
        <parent link="base"/>
        <child link="left_hip"/>
        <origin xyz="0.04305 0.05532 -0.03475" rpy="0 0 0"/>
        <axis xyz="-1 0 0"/>
        <limit lower="-1.57" upper="1.57" effort="1.667" velocity="5.5"/>
    </joint>

    <link name="left_upper_middle">
        <visual>
            <geometry>
                <mesh filename="Left_Upper_Middle.stl" scale="0.001 0.001 0.001"/>
            </geometry>
            <material name="leg_color">
                <color rgba="1 0 0 1"/>
            </material>
        </visual>
        <collision>
            <geometry>
                <mesh filename="Left_Upper_Middle.stl" scale="0.001 0.001 0.001"/>
            </geometry >
        </collision >
        <inertial>
            <mass value="0.049"/>
            <origin xyz="-0.0308	0.00547	-0.0518"/>
            <inertia ixx="0.000059826" ixy="-0.000002259" ixz="0.000021726" iyy="0.000072203" iyz="0.000013527" izz="0.000055251"/>
        </inertial>
    </link>
    <joint name="left_hip_TO_left_upper_middle" type="revolute">
        <parent link="left_hip"/>
        <child link="left_upper_middle"/>
        <origin xyz="-0.063 0.0179 -0.00075" rpy="0 0 0"/>
        <axis xyz="0 1 0"/>
        <limit lower="-1.57" upper="1.57" effort="1.667" velocity="5.5"/>
    </joint>

    <link name="left_lower">
        <visual>
            <geometry>
                <mesh filename="Left_Lower.stl" scale="0.001 0.001 0.001"/>
            </geometry>
            <material name="leg_color">
                <color rgba="1 0 0 1"/>
            </material>
        </visual>
        <collision>
            <geometry>
                <mesh filename="Left_Lower.stl" scale="0.001 0.001 0.001"/>
            </geometry >
        </collision >
        <inertial>
            <mass value="0.034"/>
            <origin xyz="0.05351	-0.00025	-0.03579"/>
            <inertia ixx="0.000017601" ixy="0.000000000" ixz="-0.000022865" iyy="0.000059724" iyz="-0.000000000" izz="0.000045137"/>
        </inertial>
    </link>
    <joint name="left_upper_middle_TO_left_lower" type="revolute">
        <parent link="left_upper_middle"/>
        <child link="left_lower"/>
        <origin xyz="-0.06764 -0.0079 -0.09912" rpy="0 0 0"/>
        <axis xyz="0 1 0"/>
        <limit lower="-3.14" upper="3.14" effort="1.667" velocity="5.5"/>
    </joint>

    <link name="left_feet">
        <visual>
            <geometry>
                <mesh filename="Left_Feet.stl" scale="0.001 0.001 0.001"/>
            </geometry>
            <material name="feet_color">
                <color rgba="0 0 1 1"/>
            </material>
        </visual>
        <collision>
            <geometry>
                <mesh filename="Left_Feet.stl" scale="0.001 0.001 0.001"/>
            </geometry >
        </collision >
        <inertial>
            <mass value="0.016"/>
            <origin xyz="0.0125	-0.008	-0.00813"/>
            <inertia ixx="0.000009026" ixy="0.000000000" ixz="0.000000000" iyy="0.000025134" iyz="0.000000000" izz="0.000033852"/>
        </inertial>
    </link>
    <joint name="left_lower_TO_left_feet" type="revolute">
        <parent link="left_lower"/>
        <child link="left_feet"/>
        <origin xyz="0.09395 0.0055 -0.07466" rpy="0 0 0"/>
        <axis xyz="0 1 0"/>
        <limit lower="-1.57" upper="1.57"/>
    </joint>



    <link name="right_hip">
        <visual>
            <geometry>
                <mesh filename="Right_Hip.stl" scale="0.001 0.001 0.001"/>
            </geometry>
            <material name="hip_color">
                <color rgba="0 1 1 1"/>
            </material>
        </visual>
        <collision>
            <geometry>
                <mesh filename="Right_Hip.stl" scale="0.001 0.001 0.001"/>
            </geometry >
        </collision >
        <inertial>
            <mass value="0.137"/>
            <origin xyz="-0.03864	-0.00844	-0.00007"/>
            <inertia ixx="0.000045031" ixy="-0.000002018" ixz="-0.000000001" iyy="0.000030577" iyz="0.000000396" izz="0.000068434"/>
        </inertial>
    </link>
    <joint name="base_TO_right_hip" type="revolute">
        <parent link="base"/>
        <child link="right_hip"/>
        <origin xyz="0.04305 -0.05528 -0.03475" rpy="0 0 0"/>
        <axis xyz="-1 0 0"/>
        <limit lower="-1.57" upper="1.57" effort="1.667" velocity="5.5"/>
    </joint>

    <link name="right_upper_middle">
        <visual>
            <geometry>
                <mesh filename="Right_Upper_Middle.stl" scale="0.001 0.001 0.001"/>
            </geometry>
            <material name="leg_color">
                <color rgba="1 0 0 1"/>
            </material>
        </visual>
        <collision>
            <geometry>
                <mesh filename="Right_Upper_Middle.stl" scale="0.001 0.001 0.001"/>
            </geometry >
        </collision >
        <inertial>
            <mass value="0.049"/>
            <origin xyz="-0.03005	-0.0055	-0.05172"/>
            <inertia ixx="0.000060253" ixy="0.000002198" ixz="0.000021915" iyy="0.000072654" iyz="-0.000013639" izz="0.000055446"/>
        </inertial>
    </link>
    <joint name="right_hip_TO_right_upper_middle" type="revolute">
        <parent link="right_hip"/>
        <child link="right_upper_middle"/>
        <origin xyz="-0.063 -0.0179 -0.00075" rpy="0 0 0"/>
        <axis xyz="0 1 0"/>
        <limit lower="-1.57" upper="1.57" effort="1.667" velocity="5.5"/>
    </joint>

    <link name="right_lower">
        <visual>
            <geometry>
                <mesh filename="Right_Lower.stl" scale="0.001 0.001 0.001"/>
            </geometry>
            <material name="leg_color">
                <color rgba="1 0 0 1"/>
            </material>
        </visual>
        <collision>
            <geometry>
                <mesh filename="Right_Lower.stl" scale="0.001 0.001 0.001"/>
            </geometry >
        </collision >
        <inertial>
            <mass value="0.034"/>
            <origin xyz="0.05351	0.0025	-0.03579"/>
            <inertia ixx="0.000017601" ixy="0.000000000" ixz="-0.000028864" iyy="0.000059723" iyz="-0.000000000" izz="0.000045136"/>
        </inertial>
    </link>
    <joint name="right_upper_middle_TO_right_lower" type="revolute">
        <parent link="right_upper_middle"/>
        <child link="right_lower"/>
        <origin xyz="-0.06764, 0.0079, -0.09912" rpy="0 0 0"/>
        <axis xyz="0 1 0"/>
        <limit lower="-3.14" upper="3.14" effort="1.667" velocity="5.5"/>
    </joint>

    <link name="right_feet">
        <visual>
            <geometry>
                <mesh filename="Right_Feet.stl" scale="0.001 0.001 0.001"/>
            </geometry>
            <material name="feet_color">
                <color rgba="0 0 1 1"/>
            </material>
        </visual>
        <collision>
            <geometry>
                <mesh filename="Right_Feet.stl" scale="0.001 0.001 0.001"/>
            </geometry >
        </collision >
        <inertial>
            <mass value="0.016"/>
            <origin xyz="0.0125	0.008	-0.00813"/>
            <inertia ixx="0.000009026" ixy="0.000000000" ixz="0.000000000" iyy="0.000025134" iyz="0.000000000" izz="0.000033852"/>
        </inertial>
    </link>
    <joint name="right_lower_TO_right_feet" type="revolute">
        <parent link="right_lower"/>
        <child link="right_feet"/>
        <origin xyz="0.09395 -0.0055 -0.07466" rpy="0 0 0"/>
        <axis xyz="0 1 0"/>
        <limit lower="-1.57" upper="1.57"/>
    </joint>


</robot>